<mujoco >
	<include file="shared_config.xml"></include>
	<worldbody >
		<include file="sawyer_xyz_base.xml"></include>
		<body name="obj" pos="-0.10103808873836341 0.6000094978098961 0.02">
			<geom material="object" conaffinity="1" contype="1" condim="3" friction="1.0 0.1 0.002" density="18394.056553400165" mesh="object_mesh" rgba="1 1 1 1" type="mesh"/>
			<joint name="objjoint" type="free" limited="false" damping="0.0" armature="0"/>
			<inertial pos="0 0 0" mass=".1" diaginertia="100000 100000 100000"/>
		</body>
		<body name="goal" pos="0.0 0.9 0.02">
			<body name="dragonball1" pos="0.075 0 0.06">
				<geom rgba="1 0 1 1" type="sphere" size="0.005 0.005 0.005"/>
			</body>
			<body name="dragonball2" pos="-0.075 0 0.06">
				<geom rgba="1 0 1 1" type="sphere" size="0.005 0.005 0.005"/>
			</body>
			<geom name="goal_bottom" rgba="1 1 0 1" type="box" pos="0 0 0.005" size="0.075 0.075 0.001" contype="1" conaffinity="0"  mass="1000"/>
			<geom name="goal_wall1" rgba="1 1 1 1" type="box" pos="0.0 0.075 0.034" size="0.075 0.001 0.03" contype="0" conaffinity="0" mass="1000"/>
			<geom name="goal_wall2" rgba="1 1 1 1" type="box" pos="0.0 -0.075 0.034" size="0.075 0.001 0.03" contype="0" conaffinity="0" mass="1000"/>
			<geom name="goal_wall3" rgba="1 1 1 1" type="box" pos="0.075 0 0.034" size="0.001 0.075 0.03" contype="0" conaffinity="0" mass="1000"/>
			<geom name="goal_wall4" rgba="1 1 1 1" type="box" pos="-0.076 0 0.034" size="0.001 0.075 0.03" contype="0" conaffinity="0" mass="1000"/>
			<geom rgba="1 1 1 1" type="capsule" fromto="0.073 0.073 0.0075 0.073 0.073 0.06" size="0.005" contype="0" conaffinity="0"/>
			<geom rgba="1 1 1 1" type="capsule" fromto="0.073 -0.073 0.0075 0.073 -0.073 0.06" size="0.005" contype="0" conaffinity="0"/>
			<geom rgba="1 1 1 1" type="capsule" fromto="-0.073 0.073 0.0075 -0.073 0.073 0.06" size="0.005" contype="0" conaffinity="0"/>
			<geom rgba="1 1 1 1" type="capsule" fromto="-0.073 -0.073 0.0075 -0.073 -0.073 0.06" size="0.005" contype="0" conaffinity="0"/>
			<joint name="goal_slidey" type="slide" pos="0 0 0" axis="0 1 0" range="-10.3213 10.3" damping="1.0"/>
			<joint name="goal_slidex" type="slide" pos="0 0 0" axis="1 0 0" range="-10.3213 10.3" damping="1.0"/>
		</body>
	</worldbody>
	<asset >
		<mesh file="/home/kevin/gym/gym/envs/mujoco/assets/sim_push_xmls/mujoco_models/vase1.stl" name="object_mesh" scale="0.0003035223549214133 0.0003035223549214133 0.0003035223549214133"/>
		<texture name="object" file="/home/kevin/gym/gym/envs/mujoco/assets/sim_push_xmls/textures/obj_textures/banded_0002.png"/>
		<material shininess="0.3" specular="1" name="object" rgba="0.9 0.9 0.9 1" texture="object"/>
	</asset>
	<actuator >
		<position ctrllimited="true" ctrlrange="-1 1" joint="r_close" kp="400" user="1"/>
		<position ctrllimited="true" ctrlrange="-1 1" joint="l_close" kp="400" user="1"/>
	</actuator>
</mujoco>
